[ERROR] RuntimeError: Directory './blog' does not exist
Traceback (most recent call last):
  File "/var/lang/lib/python3.12/importlib/__init__.py", line 90, in import_module
    return _bootstrap._gcd_import(name[level:], package, level)
  File "<frozen importlib._bootstrap>", line 1387, in _gcd_import
  File "<frozen importlib._bootstrap>", line 1360, in _find_and_load
  File "<frozen importlib._bootstrap>", line 1331, in _find_and_load_unlocked
  File "<frozen importlib._bootstrap>", line 935, in _load_unlocked
  File "<frozen importlib._bootstrap_external>", line 995, in exec_module
  File "<frozen importlib._bootstrap>", line 488, in _call_with_frames_removed
  File "/var/task/vc__handler__python.py", line 14, in <module>
    __vc_spec.loader.exec_module(__vc_module)
  File "<frozen importlib._bootstrap_external>", line 995, in exec_module
  File "<frozen importlib._bootstrap>", line 488, in _call_with_frames_removed
  File "/var/task/main.py", line 29, in <module>
    app.mount("/blog", StaticFiles(directory="./blog", html=True), name="static")
  File "/var/task/starlette/staticfiles.py", line 56, in __init__
    raise RuntimeError(f"Directory '{directory}' does not exist")
INIT_REPORT Init Duration: 2771.28 ms	Phase: invoke	Status: error	Error Type: Runtime.Unknown
